/u/athbagde/anaconda3/envs/trial_2/lib/python3.9/site-packages/torch/distributed/launch.py:178: FutureWarning: The module torch.distributed.launch is deprecated
and will be removed in future. Use torchrun.
Note that --use_env is set by default in torchrun.
If your script expects `--local_rank` argument to be set, please
change it to read from `os.environ['LOCAL_RANK']` instead. See 
https://pytorch.org/docs/stable/distributed.html#launch-utility for 
further instructions

  warnings.warn(
WARNING:torch.distributed.run:
*****************************************
Setting OMP_NUM_THREADS environment variable for each process to be 1 in default, to avoid your system being overloaded, please further tune the variable for optimal performance in your application as needed. 
*****************************************
/u/athbagde/ccf-k2/ccf-research-kaggle-2022/models/Team_2/train.py:87: FutureWarning: The frame.append method is deprecated and will be removed from pandas in a future version. Use pandas.concat instead.
  df = df.append(df_ext)
/u/athbagde/ccf-k2/ccf-research-kaggle-2022/models/Team_2/train.py:87: FutureWarning: The frame.append method is deprecated and will be removed from pandas in a future version. Use pandas.concat instead.
  df = df.append(df_ext)
Namespace(amp=True, fold=0, encoder='coat_lite_medium', checkpoint='coat_lite_medium_768_e40', batch_size=6, pretrained=True, checkpoint_path='', continue_best=False, epoches=150, img_size=768, local_rank=0, distributed=True, device='cuda:0', world_size=2, rank=0)
Traceback (most recent call last):
Traceback (most recent call last):
  File "/u/athbagde/ccf-k2/ccf-research-kaggle-2022/models/Team_2/train.py", line 384, in <module>
  File "/u/athbagde/ccf-k2/ccf-research-kaggle-2022/models/Team_2/train.py", line 384, in <module>
    model = Timm_Unet(name=args.encoder, pretrained=args.pretrained)
  File "/u/athbagde/ccf-k2/ccf-research-kaggle-2022/models/Team_2/models.py", line 31, in __init__
    model = Timm_Unet(name=args.encoder, pretrained=args.pretrained)
  File "/u/athbagde/ccf-k2/ccf-research-kaggle-2022/models/Team_2/models.py", line 31, in __init__
    checkpoint = torch.load(checkpoint, map_location=lambda storage, loc: storage)
  File "/u/athbagde/anaconda3/envs/trial_2/lib/python3.9/site-packages/torch/serialization.py", line 699, in load
    checkpoint = torch.load(checkpoint, map_location=lambda storage, loc: storage)
  File "/u/athbagde/anaconda3/envs/trial_2/lib/python3.9/site-packages/torch/serialization.py", line 699, in load
        with _open_file_like(f, 'rb') as opened_file:with _open_file_like(f, 'rb') as opened_file:

  File "/u/athbagde/anaconda3/envs/trial_2/lib/python3.9/site-packages/torch/serialization.py", line 230, in _open_file_like
  File "/u/athbagde/anaconda3/envs/trial_2/lib/python3.9/site-packages/torch/serialization.py", line 230, in _open_file_like
    return _open_file(name_or_buffer, mode)
  File "/u/athbagde/anaconda3/envs/trial_2/lib/python3.9/site-packages/torch/serialization.py", line 211, in __init__
    return _open_file(name_or_buffer, mode)
  File "/u/athbagde/anaconda3/envs/trial_2/lib/python3.9/site-packages/torch/serialization.py", line 211, in __init__
    super(_open_file, self).__init__(open(name, mode))
FileNotFoundError: [Errno 2] No such file or directory: './weights/coat_lite_medium_384x384_f9129688.pth'
    super(_open_file, self).__init__(open(name, mode))
FileNotFoundError: [Errno 2] No such file or directory: './weights/coat_lite_medium_384x384_f9129688.pth'
ERROR:torch.distributed.elastic.multiprocessing.api:failed (exitcode: 1) local_rank: 0 (pid: 22813) of binary: /u/athbagde/anaconda3/envs/trial_2/bin/python
Traceback (most recent call last):
  File "/u/athbagde/anaconda3/envs/trial_2/lib/python3.9/runpy.py", line 197, in _run_module_as_main
    return _run_code(code, main_globals, None,
  File "/u/athbagde/anaconda3/envs/trial_2/lib/python3.9/runpy.py", line 87, in _run_code
    exec(code, run_globals)
  File "/u/athbagde/anaconda3/envs/trial_2/lib/python3.9/site-packages/torch/distributed/launch.py", line 193, in <module>
    main()
  File "/u/athbagde/anaconda3/envs/trial_2/lib/python3.9/site-packages/torch/distributed/launch.py", line 189, in main
    launch(args)
  File "/u/athbagde/anaconda3/envs/trial_2/lib/python3.9/site-packages/torch/distributed/launch.py", line 174, in launch
    run(args)
  File "/u/athbagde/anaconda3/envs/trial_2/lib/python3.9/site-packages/torch/distributed/run.py", line 752, in run
    elastic_launch(
  File "/u/athbagde/anaconda3/envs/trial_2/lib/python3.9/site-packages/torch/distributed/launcher/api.py", line 131, in __call__
    return launch_agent(self._config, self._entrypoint, list(args))
  File "/u/athbagde/anaconda3/envs/trial_2/lib/python3.9/site-packages/torch/distributed/launcher/api.py", line 245, in launch_agent
    raise ChildFailedError(
torch.distributed.elastic.multiprocessing.errors.ChildFailedError: 
============================================================
train.py FAILED
------------------------------------------------------------
Failures:
[1]:
  time      : 2023-02-24_20:24:20
  host      : ross.cns.iu.edu
  rank      : 1 (local_rank: 1)
  exitcode  : 1 (pid: 22814)
  error_file: <N/A>
  traceback : To enable traceback see: https://pytorch.org/docs/stable/elastic/errors.html
------------------------------------------------------------
Root Cause (first observed failure):
[0]:
  time      : 2023-02-24_20:24:20
  host      : ross.cns.iu.edu
  rank      : 0 (local_rank: 0)
  exitcode  : 1 (pid: 22813)
  error_file: <N/A>
  traceback : To enable traceback see: https://pytorch.org/docs/stable/elastic/errors.html
============================================================
