/u/athbagde/anaconda3/envs/kaggle_2/lib/python3.9/site-packages/torch/distributed/launch.py:178: FutureWarning: The module torch.distributed.launch is deprecated
and will be removed in future. Use torchrun.
Note that --use_env is set by default in torchrun.
If your script expects `--local_rank` argument to be set, please
change it to read from `os.environ['LOCAL_RANK']` instead. See 
https://pytorch.org/docs/stable/distributed.html#launch-utility for 
further instructions

  warnings.warn(
WARNING:torch.distributed.run:
*****************************************
Setting OMP_NUM_THREADS environment variable for each process to be 1 in default, to avoid your system being overloaded, please further tune the variable for optimal performance in your application as needed. 
*****************************************
/u/athbagde/anaconda3/envs/kaggle_2/lib/python3.9/site-packages/torchvision/io/image.py:13: UserWarning: Failed to load image Python extension: libc10_cuda.so: cannot open shared object file: No such file or directory
  warn(f"Failed to load image Python extension: {e}")
/u/athbagde/anaconda3/envs/kaggle_2/lib/python3.9/site-packages/torchvision/io/image.py:13: UserWarning: Failed to load image Python extension: libc10_cuda.so: cannot open shared object file: No such file or directory
  warn(f"Failed to load image Python extension: {e}")
Traceback (most recent call last):
  File "/u/athbagde/ccf-k2/ccf-research-kaggle-2022/models/Team_2/train.py", line 35, in <module>
    from sklearn.metrics import mean_squared_error, log_loss
ModuleNotFoundError: No module named 'sklearn'
Traceback (most recent call last):
  File "/u/athbagde/ccf-k2/ccf-research-kaggle-2022/models/Team_2/train.py", line 35, in <module>
    from sklearn.metrics import mean_squared_error, log_loss
ModuleNotFoundError: No module named 'sklearn'
ERROR:torch.distributed.elastic.multiprocessing.api:failed (exitcode: 1) local_rank: 0 (pid: 2305977) of binary: /u/athbagde/anaconda3/envs/kaggle_2/bin/python
Traceback (most recent call last):
  File "/u/athbagde/anaconda3/envs/kaggle_2/lib/python3.9/runpy.py", line 197, in _run_module_as_main
    return _run_code(code, main_globals, None,
  File "/u/athbagde/anaconda3/envs/kaggle_2/lib/python3.9/runpy.py", line 87, in _run_code
    exec(code, run_globals)
  File "/u/athbagde/anaconda3/envs/kaggle_2/lib/python3.9/site-packages/torch/distributed/launch.py", line 193, in <module>
    main()
  File "/u/athbagde/anaconda3/envs/kaggle_2/lib/python3.9/site-packages/torch/distributed/launch.py", line 189, in main
    launch(args)
  File "/u/athbagde/anaconda3/envs/kaggle_2/lib/python3.9/site-packages/torch/distributed/launch.py", line 174, in launch
    run(args)
  File "/u/athbagde/anaconda3/envs/kaggle_2/lib/python3.9/site-packages/torch/distributed/run.py", line 752, in run
    elastic_launch(
  File "/u/athbagde/anaconda3/envs/kaggle_2/lib/python3.9/site-packages/torch/distributed/launcher/api.py", line 131, in __call__
    return launch_agent(self._config, self._entrypoint, list(args))
  File "/u/athbagde/anaconda3/envs/kaggle_2/lib/python3.9/site-packages/torch/distributed/launcher/api.py", line 245, in launch_agent
    raise ChildFailedError(
torch.distributed.elastic.multiprocessing.errors.ChildFailedError: 
============================================================
train.py FAILED
------------------------------------------------------------
Failures:
[1]:
  time      : 2023-02-22_11:31:12
  host      : mccarthy.cns.iu.edu
  rank      : 1 (local_rank: 1)
  exitcode  : 1 (pid: 2305978)
  error_file: <N/A>
  traceback : To enable traceback see: https://pytorch.org/docs/stable/elastic/errors.html
------------------------------------------------------------
Root Cause (first observed failure):
[0]:
  time      : 2023-02-22_11:31:12
  host      : mccarthy.cns.iu.edu
  rank      : 0 (local_rank: 0)
  exitcode  : 1 (pid: 2305977)
  error_file: <N/A>
  traceback : To enable traceback see: https://pytorch.org/docs/stable/elastic/errors.html
============================================================
